<mujoco model="dual_piper_description">
    <compiler angle="radian" />
    <size njmax="1000" nconmax="200" /> 
    
    <visual>
        <global offwidth="1920" offheight="1080" />
        <quality shadowsize="4096" />
        <headlight ambient="0.2 0.2 0.2" />
    </visual>

    <asset>
        <texture type="skybox" builtin="gradient" rgb1="0.05 0.05 0.05" rgb2="0.15 0.15 0.18" width="512" height="512"/>
        <texture name="texplane" type="2d" builtin="checker" rgb1="0.1 0.1 0.1" rgb2="0.15 0.15 0.15" width="512" height="512" mark="edge" markrgb="0.3 0.3 0.3"/>
        <material name="matplane" reflectance="0.2" texture="texplane" texrepeat="2 2" texuniform="true"/>
        <material name="piper_black" rgba="0.035 0.040 0.045 1" specular="0.25" shininess="0.20"/>
        <material name="piper_graphite" rgba="0.120 0.130 0.140 1" specular="0.35" shininess="0.25"/>
        <material name="piper_gray" rgba="0.320 0.340 0.360 1" specular="0.40" shininess="0.30"/>
        <material name="piper_silver" rgba="0.580 0.600 0.620 1" specular="0.50" shininess="0.35"/>

        <mesh name="base_link" file="meshes/base_link.STL" />
        <mesh name="link1" file="meshes/link1.STL" />
        <mesh name="link2" file="meshes/link2.STL" />
        <mesh name="link3" file="meshes/link3.STL" />
        <mesh name="link4" file="meshes/link4.STL" />
        <mesh name="link5" file="meshes/link5.STL" />
        <mesh name="link6" file="meshes/link6.STL" />
        <mesh name="gripper_base" file="meshes/gripper_base.STL" />
        <mesh name="link7" file="meshes/link7.STL" />
        <mesh name="link8" file="meshes/link8.STL" />
    </asset>

    <worldbody>
        <light directional="true" diffuse="0.8 0.8 0.8" specular="0.3 0.3 0.3" pos="0 0 5" dir="0 0 -1" castshadow="true"/>
        <light directional="true" diffuse="0.3 0.3 0.4" pos="2 2 4" dir="-2 -2 -4" castshadow="false"/>
        <light directional="true" diffuse="0.3 0.3 0.4" pos="-2 -2 4" dir="2 2 -4" castshadow="false"/>

        <geom name="floor" pos="0 0 0" size="4 4 0.1" type="plane" material="matplane" condim="3"/>

        <body name="base_izquierdo" pos="0 0.35 0">
            <geom type="mesh" material="piper_black" mesh="base_link" />
            <body name="izq_link1" pos="0 0 0.123">
                <inertial pos="0.000121505 0.000104632 -0.00438597" quat="0.486797 0.49897 -0.50059 0.513292" mass="0.215052" diaginertia="0.000116369 0.00010964 9.9555e-05" />
                <joint name="izq_joint1" pos="0 0 0" axis="0 0 1" limited="true" range="-2.618 2.168" damping="300"/>
                <geom type="mesh" material="piper_black" mesh="link1" />
                <body name="izq_link2" pos="0 0 0" quat="0.0356735 -0.0356786 -0.706207 -0.706205">
                    <inertial pos="0.198666 -0.0109269 0.00142122" quat="0.0189031 0.705267 -0.0456298 0.707219" mass="0.463914" diaginertia="0.00104423 0.0010069 0.000207486" />
                    <joint name="izq_joint2" pos="0 0 0" axis="0 0 1" limited="true" range="0 3.14" damping="100"/>
                    <geom type="mesh" material="piper_gray" mesh="link2" />
                    <body name="izq_link3" pos="0.28503 0 0" quat="0.637536 0 0 -0.77042">
                        <inertial pos="-0.0202738 -0.133915 -0.000458683" quat="0.528127 0.491307 -0.505056 0.473938" mass="0.219942" diaginertia="0.000201238 0.000190068 7.08709e-05" />
                        <joint name="izq_joint3" pos="0 0 0" axis="0 0 1" limited="true" range="-2.967 0" damping="20"/>
                        <geom type="mesh" material="piper_gray" mesh="link3" />
                        <body name="izq_link4" pos="-0.021984 -0.25075 0" quat="0.707105 0.707108 0 0">
                            <inertial pos="-9.66636e-05 0.000876064 -0.00496881" quat="0.512749 0.48584 0.481646 0.518714" mass="0.131814" diaginertia="5.1333e-05 4.14831e-05 3.96892e-05" />
                            <joint name="izq_joint4" pos="0 0 0" axis="0 0 1" limited="true" range="-1.745 1.745" damping="5"/>
                            <geom type="mesh" material="piper_black" mesh="link4" />
                            <body name="izq_link5" pos="0 0 0" quat="0.707105 -0.707108 0 0">
                                <inertial pos="-4.10554e-05 -0.0566487 -0.00372058" quat="0.492375 0.506639 0.49332 0.507463" mass="0.134101" diaginertia="5.27778e-05 4.60364e-05 4.10994e-05" />
                                <joint name="izq_joint5" pos="0 0 0" axis="0 0 1" limited="true" range="-1.22 1.22" damping="2"/>
                                <geom type="mesh" material="piper_graphite" mesh="link5" />
                                <body name="izq_link6" pos="8.8259e-05 -0.091 0" quat="0.707105 0.707108 0 0">
                                    <inertial pos="-0.000179422 7.72241e-05 0.0305765" quat="0.498967 0.497649 -0.502223 0.501147" mass="0.152309" diaginertia="0.000119759 0.000110059 4.99704e-05" />
                                    <joint name="izq_joint6" pos="0 0 0" axis="0 0 1" limited="true" range="-2.0944 2.0944" damping="0.1"/>
                                    <geom type="mesh" material="piper_silver" mesh="link6" />
                                    <geom type="mesh" material="piper_graphite" mesh="gripper_base" />
                                    <body name="izq_link7" pos="0 0 0.1358" quat="0.707105 0.707108 0 0">
                                        <inertial pos="0.000651232 -0.049193 0.00972259" quat="0.519774 0.479905 -0.436488 0.555881" mass="0.0303535" diaginertia="1.60353e-05 1.14217e-05 5.97329e-06" />
                                        <joint name="izq_joint7" pos="0 0 0" axis="0 0 1" type="slide" limited="true" range="0 0.035" damping="100"/>
                                        <geom type="mesh" material="piper_black" mesh="link7" />
                                    </body>
                                    <body name="izq_link8" pos="0 0 0.1358" quat="-2.59734e-06 -2.59735e-06 -0.707108 -0.707105">
                                        <inertial pos="0.000651232 -0.049193 0.00972259" quat="0.519774 0.479905 -0.436488 0.555881" mass="0.0303535" diaginertia="1.60353e-05 1.14217e-05 5.97329e-06" />
                                        <joint name="izq_joint8" pos="0 0 0" axis="0 0 -1" type="slide" limited="true" range="-0.035 0" damping="100"/>
                                        <geom type="mesh" material="piper_black" mesh="link8" />
                                    </body>
                                </body>
                            </body>
                        </body>
                    </body>
                </body>
            </body>
        </body>

        <body name="base_derecho" pos="0 -0.35 0">
            <geom type="mesh" material="piper_black" mesh="base_link" />
            <body name="der_link1" pos="0 0 0.123">
                <inertial pos="0.000121505 0.000104632 -0.00438597" quat="0.486797 0.49897 -0.50059 0.513292" mass="0.215052" diaginertia="0.000116369 0.00010964 9.9555e-05" />
                <joint name="der_joint1" pos="0 0 0" axis="0 0 1" limited="true" range="-2.618 2.168" damping="300"/>
                <geom type="mesh" material="piper_black" mesh="link1" />
                <body name="der_link2" pos="0 0 0" quat="0.0356735 -0.0356786 -0.706207 -0.706205">
                    <inertial pos="0.198666 -0.0109269 0.00142122" quat="0.0189031 0.705267 -0.0456298 0.707219" mass="0.463914" diaginertia="0.00104423 0.0010069 0.000207486" />
                    <joint name="der_joint2" pos="0 0 0" axis="0 0 1" limited="true" range="0 3.14" damping="100"/>
                    <geom type="mesh" material="piper_gray" mesh="link2" />
                    <body name="der_link3" pos="0.28503 0 0" quat="0.637536 0 0 -0.77042">
                        <inertial pos="-0.0202738 -0.133915 -0.000458683" quat="0.528127 0.491307 -0.505056 0.473938" mass="0.219942" diaginertia="0.000201238 0.000190068 7.08709e-05" />
                        <joint name="der_joint3" pos="0 0 0" axis="0 0 1" limited="true" range="-2.967 0" damping="20"/>
                        <geom type="mesh" material="piper_gray" mesh="link3" />
                        <body name="der_link4" pos="-0.021984 -0.25075 0" quat="0.707105 0.707108 0 0">
                            <inertial pos="-9.66636e-05 0.000876064 -0.00496881" quat="0.512749 0.48584 0.481646 0.518714" mass="0.131814" diaginertia="5.1333e-05 4.14831e-05 3.96892e-05" />
                            <joint name="der_joint4" pos="0 0 0" axis="0 0 1" limited="true" range="-1.745 1.745" damping="5"/>
                            <geom type="mesh" material="piper_black" mesh="link4" />
                            <body name="der_link5" pos="0 0 0" quat="0.707105 -0.707108 0 0">
                                <inertial pos="-4.10554e-05 -0.0566487 -0.00372058" quat="0.492375 0.506639 0.49332 0.507463" mass="0.134101" diaginertia="5.27778e-05 4.60364e-05 4.10994e-05" />
                                <joint name="der_joint5" pos="0 0 0" axis="0 0 1" limited="true" range="-1.22 1.22" damping="2"/>
                                <geom type="mesh" material="piper_graphite" mesh="link5" />
                                <body name="der_link6" pos="8.8259e-05 -0.091 0" quat="0.707105 0.707108 0 0">
                                    <inertial pos="-0.000179422 7.72241e-05 0.0305765" quat="0.498967 0.497649 -0.502223 0.501147" mass="0.152309" diaginertia="0.000119759 0.000110059 4.99704e-05" />
                                    <joint name="der_joint6" pos="0 0 0" axis="0 0 1" limited="true" range="-2.0944 2.0944" damping="0.1"/>
                                    <geom type="mesh" material="piper_silver" mesh="link6" />
                                    <geom type="mesh" material="piper_graphite" mesh="gripper_base" />
                                    <body name="der_link7" pos="0 0 0.1358" quat="0.707105 0.707108 0 0">
                                        <inertial pos="0.000651232 -0.049193 0.00972259" quat="0.519774 0.479905 -0.436488 0.555881" mass="0.0303535" diaginertia="1.60353e-05 1.14217e-05 5.97329e-06" />
                                        <joint name="der_joint7" pos="0 0 0" axis="0 0 1" type="slide" limited="true" range="0 0.035" damping="100"/>
                                        <geom type="mesh" material="piper_black" mesh="link7" />
                                    </body>
                                    <body name="der_link8" pos="0 0 0.1358" quat="-2.59734e-06 -2.59735e-06 -0.707108 -0.707105">
                                        <inertial pos="0.000651232 -0.049193 0.00972259" quat="0.519774 0.479905 -0.436488 0.555881" mass="0.0303535" diaginertia="1.60353e-05 1.14217e-05 5.97329e-06" />
                                        <joint name="der_joint8" pos="0 0 0" axis="0 0 -1" type="slide" limited="true" range="-0.035 0" damping="100"/>
                                        <geom type="mesh" material="piper_black" mesh="link8" />
                                    </body>
                                </body>
                            </body>
                        </body>
                    </body>
                </body>
            </body>
        </body>
    </worldbody>

    <actuator>
        <position name="izq_joint1" ctrllimited="true" ctrlrange="-2.618 2.618" joint="izq_joint1" kp="10000" user="1" forcelimited="true" forcerange="-20000 20000"/>
        <position name="izq_joint2" ctrllimited="true" ctrlrange="0 3.14158" joint="izq_joint2" kp="2000" user="1" forcelimited="true" forcerange="-20000 20000"/>
        <position name="izq_joint3" ctrllimited="true" ctrlrange="-2.697 0" joint="izq_joint3" kp="500" user="1" forcelimited="true" forcerange="-1000 1000"/>
        <position name="izq_joint4" ctrllimited="true" ctrlrange="-1.832 1.832" joint="izq_joint4" kp="50" user="1" forcelimited="true" forcerange="-70 70"/>
        <position name="izq_joint5" ctrllimited="true" ctrlrange="-1.22 1.22" joint="izq_joint5" kp="20" user="1" forcelimited="true" forcerange="-50 50"/>
        <position name="izq_joint6" ctrllimited="true" ctrlrange="-3.14158 3.14158" joint="izq_joint6" kp="5" user="1" forcelimited="true" forcerange="-6 6"/>
        <position name="izq_joint7" ctrllimited="true" ctrlrange="0 0.0475" joint="izq_joint7" kp="10000" user="1" forcelimited="true" forcerange="-100 100"/>
        <position name="izq_joint8" ctrllimited="true" ctrlrange="-0.0475 0" joint="izq_joint8" kp="10000" user="1" forcelimited="true" forcerange="-100 100"/>

        <position name="der_joint1" ctrllimited="true" ctrlrange="-2.618 2.618" joint="der_joint1" kp="10000" user="1" forcelimited="true" forcerange="-20000 20000"/>
        <position name="der_joint2" ctrllimited="true" ctrlrange="0 3.14158" joint="der_joint2" kp="2000" user="1" forcelimited="true" forcerange="-20000 20000"/>
        <position name="der_joint3" ctrllimited="true" ctrlrange="-2.697 0" joint="der_joint3" kp="500" user="1" forcelimited="true" forcerange="-1000 1000"/>
        <position name="der_joint4" ctrllimited="true" ctrlrange="-1.832 1.832" joint="der_joint4" kp="50" user="1" forcelimited="true" forcerange="-70 70"/>
        <position name="der_joint5" ctrllimited="true" ctrlrange="-1.22 1.22" joint="der_joint5" kp="20" user="1" forcelimited="true" forcerange="-50 50"/>
        <position name="der_joint6" ctrllimited="true" ctrlrange="-3.14158 3.14158" joint="der_joint6" kp="5" user="1" forcelimited="true" forcerange="-6 6"/>
        <position name="der_joint7" ctrllimited="true" ctrlrange="0 0.0475" joint="der_joint7" kp="10000" user="1" forcelimited="true" forcerange="-100 100"/>
        <position name="der_joint8" ctrllimited="true" ctrlrange="-0.0475 0" joint="der_joint8" kp="10000" user="1" forcelimited="true" forcerange="-100 100"/>
    </actuator>
</mujoco>
